Workbook

Sheet Todos
A1: Nombre | B1: Categoría | C1: Grupo | D1: Dirección | E1: Teléfono | F1: Latitud | G1: Longitud | H1: Rating | I1: Cant. Reseñas | J1: Descripción | K1: Estado Verificación | L1: Place ID | M1: Fuente | N1: Estado Auditoría (Lote) | O1: Confianza | P1: Observaciones | Q1: Evidencia / Fuente
A2: Vidriería y Ferretería Uruguay | B2: Ferretería | C2: comercios | D2: Blvd. Hipólito Yrigoyen 1368, Concepción del Uruguay, Entre Ríos, Argentina | E2: +54 3442 43-3072 | F2: -32.479238 | G2: -58.245475 | K2: Verificado (auditoría web múltiples fuentes) | L2: ChIJoZINXQDbr5URTtf4Nl_DDlw | M2: NUEVOSLUGARES5 | N2: ✅ Verificado | O2: Alta | P2: Confirmado por al menos 3 fuentes independientes (guía comercial redargentina, corralonpremium, redes sociales propias) con dirección y rubro coincidentes. | Q2: miguiaargentina.com.ar; redargentina.com.ar; corralonpremium.com.ar; instagram.com/vidrieriayferreteriauruguay
A3: Bulonera Uruguay | B3: Ferretería/Bulonería | C3: comercios | D3: Blvd. los Constituyentes 289, E3260 Concepción del Uruguay, Entre Ríos, Argentina | E3: +54 3442 65-4686 | F3: -32.482482 | G3: -58.243441 | K3: Verificado (auditoría web - fuente única) | L3: ChIJrZW2sH3br5URb3XonRCCv-s | M3: NUEVOSLUGARES5 | N3: ✅ Verificado | O3: Media | P3: Existencia confirmada por publicación propia en Instagram describiendo el rubro (buloneria/herramientas). No se hallaron directorios comerciales adicionales que la listen. | Q3: instagram.com/p/DXMfqq2gJYp
A4: Corralón y Ferreteria Burmer | B4: Ferretería/Corralón | C4: comercios | D4: Blvd. 12 de Octubre 1513, E3260 Concepción del Uruguay, Entre Ríos, Argentina | E4: +54 3442 43-1629 | F4: -32.475355 | G4: -58.248822 | K4: Verificado (auditoría web múltiples fuentes) | L4: ChIJ-7-3RADbr5UR2YELUOdr_U0 | M4: NUEVOSLUGARES5 | N4: ✅ Verificado | O4: Alta | P4: Confirmado por múltiples directorios comerciales independientes (Páginas Amarillas, argentino.com.ar, laguia.online, corralonpremium) con misma dirección y teléfono. | Q4: paginasamarillas.com.ar; argentino.com.ar; laguia.online; corralonpremium.com.ar
A5: Materiales Concepcion | B5: Corralón/Materiales | C5: comercios | D5: Acceso A JJ Bruno, E3260 Concepción del Uruguay, Entre Ríos, Argentina | E5: +54 3442 44-3200 | F5: -32.488081 | G5: -58.27393 | K5: Verificado (auditoría web múltiples fuentes) | L5: ChIJSWKTGizar5URieSL96nskEA | M5: NUEVOSLUGARES5 | N5: ✅ Verificado | O5: Alta | P5: Confirmado por múltiples fuentes independientes (reseñas, corralonpremium, latinoplaces) con misma dirección y teléfono. | Q5: casasprefabricadas.com.ar; corralonpremium.com.ar; ar.latinoplaces.com
A6: Ferretería LOS ROLHA | B6: Ferretería | C6: comercios | D6: Blvd. 12 de Octubre, Concepción del Uruguay, Entre Ríos, Argentina | E6: +54 3442 57-1978 | F6: -32.475908 | G6: -58.254531 | K6: Verificado (auditoría web - fuente única) | L6: ChIJpVWtKLXbr5URe4AB705zIqc | M6: NUEVOSLUGARES5 | N6: ✅ Verificado | O6: Media | P6: Listado y reseña en directorio comercial (corralonpremium) confirma existencia y rubro. No se hallaron fuentes adicionales independientes. | Q6: corralonpremium.com.ar
A7: FerreLuz | B7: Ferretería | C7: comercios | D7: Alberdi 1131, Concepción del Uruguay, Entre Ríos, Argentina | E7: +54 3442 45-4648 | F7: -32.487451 | G7: -58.239081 | K7: Verificado (Google Places) | L7: ChIJy8oKP1Xar5URQ78uc6yGGPQ | M7: NUEVOSLUGARES5 | N7: ✅ Verificado | O7: Alta | P7: CORRECCIÓN: verificación previa vía web search general había señalado una posible dirección distinta (fuente: directorio desactualizado). Google Places confirma que "Alberdi 1131" (dirección original de la planilla) es correcta. 4.6★, 103 reseñas. | Q7: Google Places (place_id: ChIJy8oKP1Xar5URQ78uc6yGGPQ) - consultado 16/07/2026. Corrige hallazgo anterior de búsqueda web genérica.
A8: Los Dos Hermanos Ferreteria | B8: Ferretería | C8: comercios | D8: Sta. Teresita 1313, E3260 Concepción del Uruguay, Entre Ríos, Argentina | E8: +54 3442 43-1146 | F8: -32.47618 | G8: -58.244968 | K8: Verificado (auditoría web múltiples fuentes) | L8: ChIJxZ86OFDar5URTdt4GOQieMc | M8: NUEVOSLUGARES5 | N8: ✅ Verificado | O8: Alta | P8: Confirmado por registro de AFIP/CUIT (rubro ferretería/materiales de construcción) y sitio web propio del comercio, mismo domicilio (Santa Teresita 1311, diferencia menor de numeración respecto al 1313 del dataset). | Q8: cuitonline.com; corralonyferreterialosdoshermanos.com
A9: BAZAR Y REGALERIA TOTE | B9: Bazar/Regalería | C9: comercios | D9: Alberdi 1788, E3260 Concepción del Uruguay, Entre Ríos, Argentina | E9: +54 9 3442 40-3248 | F9: -32.489204 | G9: -58.251279 | K9: Verificado (auditoría web - fuente única) | L9: ChIJQT3BmrPbr5URKQEYl2WHaDo | M9: NUEVOSLUGARES5 | N9: ✅ Verificado | O9: Media | P9: Listado en directorio de comercios (top-rated.online) como bazar/regalería en Concepción del Uruguay, coincide con nombre y rubro. No se hallaron fuentes adicionales. | Q9: top-rated.online
A10: Emporio Ferretero | B10: Ferretería | C10: comercios | D10: 9 de Julio 1555, Concepción del Uruguay, Entre Ríos, Argentina | E10: +54 3442 44-6397 | F10: -32.487432 | G10: -58.24716 | K10: Verificado (auditoría web múltiples fuentes) | L10: ChIJmV3cXQDbr5UR9r4V-LgmlLg | M10: NUEVOSLUGARES5 | N10: ✅ Verificado | O10: Alta | P10: Confirmado por múltiples directorios independientes (argentino.com.ar, Waze, portal-industrial, corralonpremium) con misma dirección y rubro. | Q10: argentino.com.ar; waze.com; portal-industrial.com.ar; corralonpremium.com.ar
A11: Libreria-Regaleria Quinteto | B11: Librería/Regalería | C11: comercios | D11: El Despertar del Obrero 925, E3260 Concepción del Uruguay, Entre Ríos, Argentina | E11: +54 3442 54-2532 | F11: -32.502647 | G11: -58.279539 | K11: Verificado (auditoría web - fuente única) | L11: ChIJKxNjxNfbr5UR3bh2ZukRJbo | M11: NUEVOSLUGARES5 | N11: ✅ Verificado | O11: Media | P11: Confirmado por directorio de librerías (libreriatecnicaweb.com.ar) que describe el comercio con atención 24hs y delivery, coincide con nombre y rubro. | Q11: libreriatecnicaweb.com.ar
A12: Micael 24 horas | B12: Librería/Kiosco 24hs | C12: comercios | D12: Blvd. Hipólito Yrigoyen 1068, Concepción del Uruguay, Entre Ríos, Argentina | E12: +54 3442 56-8117 | F12: -32.478256 | G12: -58.239698 | K12: Verificado (auditoría web - fuente oficial) | L12: ChIJCentG1Tar5UR74fuTxI5EnI | M12: NUEVOSLUGARES5 | N12: ✅ Verificado | O12: Alta | P12: Confirmado por comunicado oficial de la Municipalidad de Concepción del Uruguay (Programa Red con Vos) y nota periodística, listando "Librería Micael (Yrigoyen 1.068)", coincide exactamente con dirección del dataset. | Q12: cdeluruguay.gob.ar; 03442.com.ar; laprensafederal.com.ar
A13: Librería Helvetica | B13: Librería | C13: comercios | D13: 25 de Mayo 208, E3260 Concepción del Uruguay, Entre Ríos, Argentina | E13: +54 3442 58-3914 | F13: -32.481583 | G13: -58.232651 | K13: Verificado (auditoría web - fuente oficial) | L13: ChIJ0UcwJgDbr5UR5tPjVoBStzw | M13: NUEVOSLUGARES5 | N13: ✅ Verificado | O13: Alta | P13: Confirmada por múltiples notas periodísticas y la propia Municipalidad (evento "Noche de las Librerías") listando "Helvética, 25 de Mayo 208", coincide exactamente con el dataset. También listada en Feria del Libro y directorios comerciales. | Q13: cdeluruguay.gob.ar; el-libro.org.ar; analisisdigital.com.ar; aimdigital.com.ar
A14: Libreria Universal. Café y libros | B14: Librería/Café | C14: comercios | D14: 25 de Mayo 113, E3260 Concepción del Uruguay, Entre Ríos, Argentina | E14: +54 3442 46-4979 | F14: -32.483038 | G14: -58.232541 | K14: Verificado (auditoría web - fuente oficial) | L14: ChIJdwG6UQDbr5URhmtBHXXha1c | M14: NUEVOSLUGARES5 | N14: ✅ Verificado | O14: Alta | P14: Confirmada junto con Helvética en las mismas notas oficiales/periodísticas del evento "Noche de las Librerías": "Universal, 25 de Mayo 113", coincide con el dataset. | Q14: cdeluruguay.gob.ar; analisisdigital.com.ar; aimdigital.com.ar
A15: Librería Mafalda | B15: Librería | C15: comercios | D15: España 79, Concepción del Uruguay, Entre Ríos, Argentina | F15: -32.486108 | G15: -58.233817 | K15: Verificado (auditoría web múltiples fuentes) | L15: ChIJ-e8ptQDbr5UR7UiVMiyKN4k | M15: NUEVOSLUGARES5 | N15: ✅ Verificado | O15: Alta | P15: Confirmada por directorio comercial, Facebook e Instagram propios del comercio, todos coincidiendo en "España 79". Se detectaron listados antiguos con otra dirección (Alberdi 810/812) que parecen corresponder a una ubicación previa; se prioriza la evidencia más reciente (redes sociales activas) que confirma España 79. | Q15: ar.todosnegocios.com; facebook.com/people/libreriamafaldacdelu; instagram.com/libreriamafalda.cdelu
A16: Libreria Proa | B16: Librería | C16: comercios | D16: España 14, E3260 Concepción del Uruguay, Entre Ríos, Argentina | E16: +54 3442 49-8730 | F16: -32.485217 | G16: -58.233715 | K16: Verificado (auditoría web - fuente oficial) | L16: ChIJu__ZlQDbr5URInaW-a80uaM | M16: NUEVOSLUGARES5 | N16: ✅ Verificado | O16: Alta | P16: Confirmada junto con Helvética/Universal en notas oficiales/periodísticas: "Proa, España 14", coincide con el dataset. | Q16: cdeluruguay.gob.ar; analisisdigital.com.ar; aimdigital.com.ar
A17: Libreria Fabre's | B17: Librería | C17: comercios | D17: Posadas 1337, Concepción del Uruguay, Entre Ríos, Argentina | F17: -32.483899 | G17: -58.24375 | K17: Verificado (auditoría web - fuente única) | L17: ChIJScA71FLar5URohFpVxQ4KVY | M17: NUEVOSLUGARES5 | N17: ✅ Verificado | O17: Media | P17: Listada en directorio especializado de librerías (libreriatecnicaweb.com.ar) para Concepción del Uruguay, coincide nombre y rubro. No se halló confirmación independiente de la dirección exacta (Posadas 1337). | Q17: libreriatecnicaweb.com.ar
A18: Librería del Colegio | B18: Librería | C18: comercios | D18: Leguizamón 33, Concepción del Uruguay, Entre Ríos, Argentina | E18: +54 3442 57-3300 | F18: -32.484448 | G18: -58.233969 | K18: Verificado (existencia confirmada - redes sociales; rubro y zona coinciden) | L18: ChIJ-UPlRWLbr5URQExSDouxy_U | M18: NUEVOSLUGARES5 | N18: ✅ Verificado | O18: Media | P18: Existencia confirmada vía página de Facebook activa (241 seguidores) en Concepción del Uruguay, rubro librería coincide. Dirección "Leguizamón 33" y teléfono no confirmados por fuente pública independiente. | Q18: Facebook: facebook.com/p/Librería-Del-Colegio-100067391370145 - búsqueda web 16/07/2026
A19: Gestoria Jenny - Kat | B19: Gestoría | C19: comercios | D19: Bartolomé Mitre 854, Concepción del Uruguay, Entre Ríos, Argentina | E19: +54 3442 42-2503 | F19: -32.481395 | G19: -58.235477 | K19: Verificado (auditoría web múltiples fuentes) | L19: ChIJoZINXQDbr5URmifJWKfVsEE | M19: NUEVOSLUGARES5 | N19: ✅ Verificado | O19: Alta | P19: Confirmada por múltiples directorios independientes (Páginas Amarillas, argentino.com.ar, miguiaargentina, laguia.online) con misma dirección (Mitre 854) y teléfono. | Q19: paginasamarillas.com.ar; argentino.com.ar; guia-entre-rios.miguiaargentina.com.ar; laguia.online
A20: GESTORIA FG | B20: Gestoría | C20: comercios | D20: Enrique Gasc 399, E3260 Concepción del Uruguay, Entre Ríos, Argentina | E20: +54 9 3442 55-4860 | F20: -32.492168 | G20: -58.242274 | K20: Verificado (Google Places) | L20: ChIJdZhX-w7br5URQW1VIIM9L1k | M20: NUEVOSLUGARES5 | N20: ✅ Verificado | O20: Alta | P20: Coincidencia exacta de nombre, dirección y teléfono en Google Places. 5.0★ (12 reseñas). | Q20: Google Places (place_id: ChIJdZhX-w7br5URQW1VIIM9L1k) - consultado 16/07/2026
A21: Gestoría del Automotor Gustavo Gonzalez | B21: Gestoría | C21: comercios | D21: Isaias Torres 917, E3260 Concepción del Uruguay, Entre Ríos, Argentina | E21: +54 3442 62-1747 | F21: -32.472764 | G21: -58.248926 | K21: Verificado (auditoría web - fuente única) | L21: ChIJpb7WK2fbr5UR6M0T5YxjPds | M21: NUEVOSLUGARES5 | N21: ✅ Verificado | O21: Media | P21: Confirmada por página de Facebook activa (294 seguidores) que identifica al titular como Mandatario Nacional del Automotor con habilitación nacional y provincial vigente. No se confirmó independientemente la dirección exacta (Isaías Torres 917). | Q21: facebook.com/GestoriaGustavoGonzalez
A22: LK Gestoría Integral | B22: Gestoría | C22: comercios | D22: Sarmiento 2032, E3260 Concepción del Uruguay, Entre Ríos, Argentina | E22: +54 3442 57-1708 | F22: -32.491483 | G22: -58.255408 | K22: Verificado (Google Places) | L22: ChIJG7l22Inbr5URjdksYbQPvTk | M22: NUEVOSLUGARES5 | N22: ✅ Verificado | O22: Alta | P22: Coincidencia exacta de nombre, dirección y teléfono en Google Places. 5.0★ (5 reseñas). | Q22: Google Places (place_id: ChIJG7l22Inbr5URjdksYbQPvTk) - consultado 16/07/2026
A23: Gestoria Automotor | B23: Gestoría | C23: comercios | D23: Ruiz Moreno 578, Concepción del Uruguay, Entre Ríos, Argentina | E23: +54 3442 47-3737 | F23: -32.47858 | G23: -58.247751 | K23: Verificado (Google Places) | L23: ChIJBXVfKdDbr5URmaZed8udSQ0 | M23: NUEVOSLUGARES5 | N23: ✅ Verificado | O23: Alta | P23: Coincidencia exacta de nombre, dirección y teléfono en Google Places. 5.0★ (4 reseñas). | Q23: Google Places (place_id: ChIJBXVfKdDbr5URmaZed8udSQ0) - consultado 16/07/2026
A24: Gestoría nº 10 - Concepción del Uruguay | B24: Gestoría | C24: comercios | D24: San Martín 1402, E3260 Concepción del Uruguay, Entre Ríos, Argentina | E24: +54 3442 42-8094 | F24: -32.487558 | G24: -58.244214 | K24: Verificado (Google Places) | L24: ChIJt9Hsuq3br5URt_c2XcZNEvU | M24: NUEVOSLUGARES5 | N24: ✅ Verificado | O24: Alta | P24: Coincidencia exacta de nombre, dirección y teléfono en Google Places. 4.0★ (14 reseñas). | Q24: Google Places (place_id: ChIJt9Hsuq3br5URt_c2XcZNEvU) - consultado 16/07/2026
A25: Gestora Automotor | B25: Gestoría | C25: comercios | D25: Artusi 2797, E3260 Concepción del Uruguay, Entre Ríos, Argentina | F25: -32.484703 | G25: -58.274541 | K25: Verificado (Google Places) | L25: ChIJWWdVVwDbr5URPkvGiH8VYI4 | M25: NUEVOSLUGARES5 | N25: ✅ Verificado | O25: Media | P25: Coincidencia exacta de nombre, dirección y teléfono en Google Places. 5.0★ (1 reseñas). | Q25: Google Places (place_id: ChIJWWdVVwDbr5URPkvGiH8VYI4) - consultado 16/07/2026
A26: Gestoría María Luz González | B26: Gestoría | C26: comercios | D26: C. Sampay 3295, Concepción del Uruguay, Entre Ríos, Argentina | E26: +54 3442 51-5194 | F26: -32.496991 | G26: -58.287514 | K26: Verificado (Google Places) | L26: ChIJX2KtNdvZr5UR8TsthGnc_X4 | M26: NUEVOSLUGARES5 | N26: ✅ Verificado | O26: Media | P26: Coincidencia exacta de nombre, dirección y teléfono en Google Places. 5.0★ (1 reseñas). | Q26: Google Places (place_id: ChIJX2KtNdvZr5UR8TsthGnc_X4) - consultado 16/07/2026
A27: L.A Estudio Contable | B27: Estudio Contable | C27: comercios | D27: Ereño 728, Concepción del Uruguay, Entre Ríos, Argentina | E27: +54 3442 53-6206 | F27: -32.488178 | G27: -58.231931 | K27: Verificado (Google Places) | L27: ChIJfbWTemnbr5URxqImc4vlNEI | M27: NUEVOSLUGARES5 | N27: ✅ Verificado | O27: Alta | P27: Coincidencia exacta de nombre, dirección y teléfono en Google Places. 5.0★ (17 reseñas). | Q27: Google Places (place_id: ChIJfbWTemnbr5URxqImc4vlNEI) - consultado 16/07/2026
A28: Gestionar | Estudio Contable y Consultoria | B28: Estudio Contable | C28: comercios | D28: 9 de Julio 1709, E3260 Concepción del Uruguay, Entre Ríos, Argentina | E28: +54 3442 57-6490 | F28: -32.488069 | G28: -58.250134 | K28: Verificado (auditoría web - sitio propio) | L28: ChIJMenKZkbbr5URNNnKf-t6VQc | M28: NUEVOSLUGARES5 | N28: ✅ Verificado | O28: Media | P28: Confirmado por página de Facebook y sitio web oficial propio (estudiocontablegestionar.com) que coincide con el nombre "Gestionar, estudio contable y consultoría" en Concepción del Uruguay. No se confirmó independientemente la dirección exacta (9 de Julio 1709). | Q28: facebook.com/estudiogestionar; estudiocontablegestionar.com
A29: AZARIO ESTUDIO CONTABLE | B29: Estudio Contable | C29: comercios | D29: Maipú 65, 3262 Concepción del Uruguay, Entre Ríos, Argentina | E29: +54 3442 66-8593 | F29: -32.485002 | G29: -58.240099 | K29: Verificado (Google Places) | L29: ChIJO8PDWMHbr5URR1xtRRkQHg0 | M29: NUEVOSLUGARES5 | N29: ✅ Verificado | O29: Alta | P29: Coincidencia exacta de nombre, dirección y teléfono en Google Places. 5.0★ (5 reseñas). | Q29: Google Places (place_id: ChIJO8PDWMHbr5URR1xtRRkQHg0) - consultado 16/07/2026
A30: Estudio jurídico y contable Medina Cavallo | B30: Estudio Jurídico/Contable | C30: comercios | D30: Posadas 174, E3260 Concepción del Uruguay, Entre Ríos, Argentina | E30: +54 9 3442 50-8582 | F30: -32.479943 | G30: -58.223892 | K30: Verificado (auditoría web - redes propias) | L30: ChIJ9fU4I4rbr5URJS639AHjQfE | M30: NUEVOSLUGARES5 | N30: ✅ Verificado | O30: Media | P30: Confirmado por cuenta de Instagram activa (3.050 seguidores) que describe a las profesionales (abogada y contadora) del estudio "Medina Cavallo". No se confirmó independientemente la dirección exacta (Posadas 174). | Q30: instagram.com/estudiojuridicoycontablemc
A31: Estudio Contable Bonnin-Francou | B31: Estudio Contable | C31: comercios | D31: Gral. Galarza 1346, Concepción del Uruguay, Entre Ríos, Argentina | F31: -32.485697 | G31: -58.243378 | K31: Verificado (Google Places) | L31: ChIJeQ82YgDbr5URazg-giyMHVM | M31: NUEVOSLUGARES5 | N31: ✅ Verificado | O31: Media | P31: Coincidencia exacta de nombre, dirección y teléfono en Google Places. sin reseñas. | Q31: Google Places (place_id: ChIJeQ82YgDbr5URazg-giyMHVM) - consultado 16/07/2026
A32: ESTUDIO EMBON | B32: Estudio Contable | C32: comercios | D32: Artigas 11, E3260 Concepción del Uruguay, Entre Ríos, Argentina | E32: +54 3442 42-4647 | F32: -32.484586 | G32: -58.23052 | K32: Verificado (Google Places) | L32: ChIJW25JM1zbr5URgcmT_2oxLcM | M32: NUEVOSLUGARES5 | N32: ✅ Verificado | O32: Alta | P32: Coincidencia exacta de nombre, dirección y teléfono en Google Places. 5.0★ (3 reseñas). | Q32: Google Places (place_id: ChIJW25JM1zbr5URgcmT_2oxLcM) - consultado 16/07/2026
A33: Estudio Contable Francou Terrile | B33: Estudio Contable | C33: comercios | D33: Eva Duarte de Perón 61 Ofi 13, E3260 Concepción del Uruguay, Entre Ríos, Argentina | E33: +54 3442 52-9772 | F33: -32.483623 | G33: -58.231595 | K33: Verificado (Google Places) | L33: ChIJD37CRIDbr5URi3-fZ2SCO3k | M33: NUEVOSLUGARES5 | N33: ✅ Verificado | O33: Media | P33: Coincidencia exacta de nombre, dirección y teléfono en Google Places. sin reseñas. | Q33: Google Places (place_id: ChIJD37CRIDbr5URi3-fZ2SCO3k) - consultado 16/07/2026
A34: Estudio Contable Bulay | B34: Estudio Contable | C34: comercios | D34: Eva Duarte de Perón 275, E3260 Concepción del Uruguay, Entre Ríos, Argentina | E34: +54 3442 42-7062 | F34: -32.480607 | G34: -58.232206 | K34: Verificado (auditoría web - fuente única) | L34: ChIJf1JH70fbr5URC1zW6FbA61E | M34: NUEVOSLUGARES5 | N34: ✅ Verificado | O34: Media | P34: Confirmado por página de Facebook activa que describe el rubro (asesoramiento impositivo, contable y laboral) coincidente con el dataset. No se confirmó independientemente la dirección exacta. | Q34: facebook.com/estudiobulay
A35: Estudio Jurídico Contable Pascal | B35: Estudio Jurídico/Contable | C35: comercios | D35: Eva Duarte de Perón 284, E3260 Concepción del Uruguay, Entre Ríos, Argentina | E35: +54 3442 40-8898 | F35: -32.480472 | G35: -58.231988 | K35: Verificado (Google Places) | L35: ChIJ_fAU_rDbr5URBdtV81cqWxs | M35: NUEVOSLUGARES5 | N35: ✅ Verificado | O35: Media | P35: Coincidencia exacta de nombre, dirección y teléfono en Google Places. 5.0★ (1 reseñas). | Q35: Google Places (place_id: ChIJ_fAU_rDbr5URBdtV81cqWxs) - consultado 16/07/2026
A36: Cr. Roberto González | B36: Contador | C36: comercios | D36: Leandro N. Alem 81, Concepción del Uruguay, Entre Ríos, Argentina | E36: +54 3442 42-6678 | F36: -32.486275 | G36: -58.234467 | K36: Verificado (auditoría web múltiples fuentes) | L36: ChIJZ1Osg0vbr5UR3T9Ymacgf6c | M36: NUEVOSLUGARES5 | N36: ✅ Verificado | O36: Alta | P36: Confirmado por múltiples directorios independientes (miguiaargentina, telexplorer, licuo, argentino.com.ar) con la misma dirección "L N Alem 81", coincide exactamente con el dataset. | Q36: guia-entre-rios.miguiaargentina.com.ar; telexplorer.com.ar; concepcion-del-uruguay.licuo.com.ar; argentino.com.ar
A37: Inmobiliaria Galotto | B37: Inmobiliaria | C37: comercios | D37: 9 de Julio 1040, E3260 Concepción del Uruguay, Entre Ríos, Argentina | E37: +54 3442 40-1452 | F37: -32.485604 | G37: -58.237925 | K37: Verificado (auditoría web múltiples fuentes) | L37: ChIJ-7-3RADbr5URXi2oNcOC0uM | M37: NUEVOSLUGARES5 | N37: ✅ Verificado | O37: Alta | P37: Confirmado por Cylex ("9 de Julio 1040", coincide exacto con el dataset), sitio web propio (galotto.com.ar) e Instagram (10K seguidores). Se detectó una dirección alternativa en otros directorios (Posadas 793) que podría corresponder a una sucursal u oficina anterior. | Q37: cylex.com.ar; instagram.com/inmobiliaria.galotto; galotto.com.ar
A38: Inmobiliaria Elsa Guionet | B38: Inmobiliaria | C38: comercios | D38: San Martín 967, E3260 Concepción del Uruguay, Entre Ríos, Argentina | E38: +54 3442 48-0468 | F38: -32.486281 | G38: -58.236548 | K38: Verificado (auditoría web múltiples fuentes) | L38: ChIJ-7-3RADbr5URlds1r3sGEGI | M38: NUEVOSLUGARES5 | N38: ✅ Verificado | O38: Alta | P38: Confirmado por Cybo y Cylex, y por reseña en aspenbienesraices.com.ar, todos coincidiendo en "San Martín 967". Cuenta con sitio propio (elsaguionet.com.ar). | Q38: es.cybo.com; cylex.com.ar; aspenbienesraices.com.ar; elsaguionet.com.ar
A39: MONTI NEGOCIOS INMOBILIARIOS | B39: Inmobiliaria | C39: comercios | D39: Ing. Henry 1712, E3260 Concepción del Uruguay, Entre Ríos, Argentina | E39: +54 9 3442 47-8117 | F39: -32.491904 | G39: -58.249559 | K39: Verificado (Google Places) | L39: ChIJdz_Up7Lbr5URiu1k63QG7eQ | M39: NUEVOSLUGARES5 | N39: ✅ Verificado | O39: Alta | P39: Coincidencia exacta de nombre, dirección y teléfono en Google Places. 4.3★ (23 reseñas). | Q39: Google Places (place_id: ChIJdz_Up7Lbr5URiu1k63QG7eQ) - consultado 16/07/2026
A40: Inmobiliaria Ramirez Muñoz & Cia | B40: Inmobiliaria | C40: comercios | D40: Alberdi 511, Concepción del Uruguay, Entre Ríos, Argentina | E40: +54 9 3442 40-8157 | F40: -32.485559 | G40: -58.228649 | K40: Verificado (auditoría web múltiples fuentes) | L40: ChIJ-7-3RADbr5URqSGMUD4JlIM | M40: NUEVOSLUGARES5 | N40: ✅ Verificado | O40: Alta | P40: Confirmado por múltiples fuentes independientes (argentino.com.ar, bienesonline.com.ar, aspenbienesraices.com.ar, sitio propio ramirezmunioz.com.ar) coincidiendo en "Alberdi 511". | Q40: argentino.com.ar; aspenbienesraices.com.ar; ramirezmunioz.com.ar
...

Sheet Resumen
A1: Resumen de Lugares
A3: Total de lugares: | B3: =COUNTA(Todos!A2:A1586) -> 1585
A5: Grupo | B5: Cantidad | D5: Categoría | E5: Cantidad
A6: alojamiento | B6: =COUNTIF(Todos!C2:C1586,A6) -> 32 | D6: Aberturas | E6: =COUNTIF(Todos!B2:B1586,D6) -> 5
A7: belleza | B7: =COUNTIF(Todos!C2:C1586,A7) -> 99 | D7: Aberturas / Carpintería de aluminio | E7: =COUNTIF(Todos!B2:B1586,D7) -> 1
A8: comercios | B8: =COUNTIF(Todos!C2:C1586,A8) -> 93 | D8: Abogado | E8: =COUNTIF(Todos!B2:B1586,D8) -> 20
A9: compras | B9: =COUNTIF(Todos!C2:C1586,A9) -> 265 | D9: Academia de idiomas | E9: =COUNTIF(Todos!B2:B1586,D9) -> 1
A10: deporte | B10: =COUNTIF(Todos!C2:C1586,A10) -> 115 | D10: Acceso ribereño | E10: =COUNTIF(Todos!B2:B1586,D10) -> 1
A11: educacion | B11: =COUNTIF(Todos!C2:C1586,A11) -> 34 | D11: Adiestramiento canino | E11: =COUNTIF(Todos!B2:B1586,D11) -> 1
A12: finanzas | B12: =COUNTIF(Todos!C2:C1586,A12) -> 104 | D12: Agencia de turismo | E12: =COUNTIF(Todos!B2:B1586,D12) -> 1
A13: gastronomia | B13: =COUNTIF(Todos!C2:C1586,A13) -> 302 | D13: Agencia de viajes | E13: =COUNTIF(Todos!B2:B1586,D13) -> 13
A14: mascotas | B14: =COUNTIF(Todos!C2:C1586,A14) -> 17 | D14: Agencia de viajes / Turismo | E14: =COUNTIF(Todos!B2:B1586,D14) -> 1
A15: naturaleza | B15: =COUNTIF(Todos!C2:C1586,A15) -> 27 | D15: Alarmas / Seguridad | E15: =COUNTIF(Todos!B2:B1586,D15) -> 1
A16: patrimonio | B16: =COUNTIF(Todos!C2:C1586,A16) -> 37 | D16: Alimentos balanceados | E16: =COUNTIF(Todos!B2:B1586,D16) -> 1
A17: salud | B17: =COUNTIF(Todos!C2:C1586,A17) -> 177 | D17: Almacén | E17: =COUNTIF(Todos!B2:B1586,D17) -> 1
A18: servicios_publicos | B18: =COUNTIF(Todos!C2:C1586,A18) -> 22 | D18: Almacén / Autoservicio | E18: =COUNTIF(Todos!B2:B1586,D18) -> 2
A19: transporte | B19: =COUNTIF(Todos!C2:C1586,A19) -> 177 | D19: Almacén / Verdulería | E19: =COUNTIF(Todos!B2:B1586,D19) -> 1
D20: Almacén de barrio | E20: =COUNTIF(Todos!B2:B1586,D20) -> 2
D21: Almacén gourmet / Panadería | E21: =COUNTIF(Todos!B2:B1586,D21) -> 1
D22: Almacén y Rotisería de Barrio | E22: =COUNTIF(Todos!B2:B1586,D22) -> 1
D23: Alojamiento | E23: =COUNTIF(Todos!B2:B1586,D23) -> 2
D24: Alojamiento Genérico | E24: =COUNTIF(Todos!B2:B1586,D24) -> 2
D25: Alojamiento/Bungalows | E25: =COUNTIF(Todos!B2:B1586,D25) -> 1
D26: Alojamiento/Cabañas | E26: =COUNTIF(Todos!B2:B1586,D26) -> 1
D27: Ambulancias | E27: =COUNTIF(Todos!B2:B1586,D27) -> 1
D28: Apart Hotel | E28: =COUNTIF(Todos!B2:B1586,D28) -> 2
D29: Arquitectura | E29: =COUNTIF(Todos!B2:B1586,D29) -> 1
D30: Arquitectura / Ingeniería | E30: =COUNTIF(Todos!B2:B1586,D30) -> 1
D31: Arroyo | E31: =COUNTIF(Todos!B2:B1586,D31) -> 3
D32: Artes marciales | E32: =COUNTIF(Todos!B2:B1586,D32) -> 1
D33: Artes marciales / Taekwondo | E33: =COUNTIF(Todos!B2:B1586,D33) -> 2
D34: Asociación civil | E34: =COUNTIF(Todos!B2:B1586,D34) -> 1
D35: Auditorio / Centro cultural | E35: =COUNTIF(Todos!B2:B1586,D35) -> 1
D36: Autoservicio | E36: =COUNTIF(Todos!B2:B1586,D36) -> 2
D37: Autoservicio / Maxikiosco 24hs | E37: =COUNTIF(Todos!B2:B1586,D37) -> 1
D38: Autoservicio / Supermercado | E38: =COUNTIF(Todos!B2:B1586,D38) -> 1
D39: Banco / Cajero | E39: =COUNTIF(Todos!B2:B1586,D39) -> 8
D40: Bar | E40: =COUNTIF(Todos!B2:B1586,D40) -> 16
D41: Bar / Hamburguesería | E41: =COUNTIF(Todos!B2:B1586,D41) -> 1
D42: Bar / Pub | E42: =COUNTIF(Todos!B2:B1586,D42) -> 1
...

Sheet Log Auditoría
A1: Metodología: comparación masiva contra base maestra de Google Places (batch por categoría+zona), matching automático, búsqueda individual solo para casos sin resolver.
A3: Grupos completados | B3: Filas | C3: Consultas usadas | D3: Ratio filas/consulta | E3: Fecha
A4: mascotas | B4: 17 | C4: 6 | D4: 2.8 | E4: 16/07/2026
A5: comercios (10 registros con verificación débil upgradeados; 83 restantes ya tenían verificación externa previa) | B5: 10 | C5: 10 | D5: 1.0 | E5: 16/07/2026
A6: patrimonio + naturaleza (6 registros débiles upgradeados de 17 totales) | B6: 6 | C6: 6 | D6: 1.0 | E6: 16/07/2026
A7: deporte + alojamiento + finanzas/compras (18 registros débiles + 1 dudoso resuelto) | B7: 19 | C7: 13 | D7: 1.5 | E7: 16/07/2026
A8: belleza (Tanda 1 - proceso de verificación rigurosa fila por fila iniciado 17/07/2026): 10 registros verificados vía Google Places API + fuentes cruzadas | B8: 10 | C8: 11 | D8: 0.9 | E8: 17/07/2026
A11: Grupos pendientes (orden top-to-bottom de la planilla) | B11: Filas totales | C11: Sin auditar (Estado Auditoría Lote = NaN)
A12: comercios | B12: 93 | C12: 0
A13: patrimonio | B13: 37 | C13: revisar
A14: naturaleza | B14: 27 | C14: revisar
A15: transporte | B15: 177 | C15: revisar
A16: deporte | B16: 115 | C16: revisar
A17: alojamiento | B17: 32 | C17: revisar
A18: finanzas | B18: 104 | C18: revisar
A19: compras | B19: 265 | C19: revisar
A20: salud | B20: 177 | C20: revisar
A21: gastronomia | B21: 302 | C21: revisar
A22: belleza | B22: 99 | C22: revisar
A23: servicios_publicos | B23: 22 | C23: revisar
A24: educacion | B24: 34 | C24: revisar
A25: oficios_tecnicos | B25: 83 | C25: revisar
A27: Comercios detectados en Google Places que NO están en la planilla (candidatos a alta) | B27: Dirección | C27: Rubro
A28: VipVet Clinica Veterinaria | B28: 9 de Julio 1427 | C28: Veterinaria
A29: NORTE - Pet shop | B29: Blvd. Hipólito Yrigoyen 611 | C29: Pet shop / forrajería
A30: Mascota Urbana Pet Shop | B30: Gral. Galarza 627 | C30: Pet shop
A31: PuppyDog PetShop | B31: República de Chile 332 | C31: Pet shop
A32: San José Petshop | B32: Posadas 1582 | C32: Pet shop
A33: Agroveterinaria 9 de Julio (2da ficha) | B33: 9 de Julio 1016 | C33: Veterinaria - posible duplicado en Google Maps de la fila 112
A35: Inconsistencias detectadas (no resueltas, requieren decisión del cliente)
A36: Fila 112 - Agroveterinaria 9 de Julio de Argacha Hirinson: existen DOS fichas de Google Places en la misma dirección (9 de Julio 1016) con teléfonos distintos (+54 3442 42-3827 vs +54 3442 42-7801 de la planilla). Podría ser el mismo comercio con doble alta en Google, o dos negocios distintos en la misma dirección.
